Workbook

Sheet Investors Details
B1: Czarlie & Ron Investments — Investor Management Dashboard
B2: Overview of capital, return liabilities, and active 36-month investment agreements.
B3: TOTAL CAPITAL INVESTED | E3: MONTHLY RETURN LIABILITY | G3: UNIQUE INVESTORS | I3: TOTAL ACTIVE TRANCHES | K3: MONTHLY RETURN RATE
B4: =SUM(J9:J18) -> 1100000 | E4: =SUM(M9:M18) -> 55000 | G4: =IFERROR(__xludf.DUMMYFUNCTION("COUNTUNIQUE(C9:C18)"),3.0) -> 3 | I4: =COUNTIF(R9:R18,"Active") -> 1 | K4: 0.05
B5: Principal Pool | E5: Active Commitments | G5: Registered Partners | I5: Active Tranches | K5: Contractual Standard
B7: Master Investor Directory
B8: Investor ID | C8: Investor Name | D8: Address | E8: Contact Email | F8: Phone | G8: Investment Type | H8: Contract Number | I8: Contract Start Date | J8: Investment Capital (PHP) | K8: Monthly Rate | L8: Contract Term | M8: Monthly Return (PHP) | N8: Maturity Date | O8: Bank Name | P8: Account Name | Q8: Bank Account # | R8: Contract Status
B9: INV-001 | C9: Janice Capinlac | D9: 59 Cambridge st. Brgy E. Rodriguez Quezon City | E9: jajacapinlac@gmail.com | G9: Initial Investment | H9: CR-2026-001 | I9: 46296 | J9: 500000 | K9: 0.05 | L9: 36 Months | M9: =J9*K9 -> 25000 | N9: =EDATE(I9,36) -> 47392 | O9: BDO | P9: Michelle C Sablay | Q9: 3970177094 | R9: Pending
B10: INV-002 | C10: Carrei Cyrell R. Mabanag | D10: Block A, Phase 2, Lot 7 Christine Village, Cauayan City, Isabela | E10: carreimabanag@gmail.com | F10: 9929044719 | G10: Initial Investment | H10: CR-2026-003 | I10: 46307 | J10: 500000 | K10: 0.05 | L10: 36 Months | M10: =J10*K10 -> 25000 | N10: =EDATE(I10,36) -> 47403 | O10: Metrobank | P10: Carrei Cyrell R. Mabanag | Q10: 1343134565749 | R10: Active
B11: INV-003 | C11: Kristal Gayle Aguinaldo | D11: 8 Coolehill Crescent Belfast, BT36 5AB | E11: kristalgayleaguinaldo24@gmail.com | F11: 7384377328 | G11: Initial Investment | H11: CR-2026-004 | I11: 46300 | J11: 100000 | K11: 0.05 | L11: 36 Months | M11: =J11*K11 -> 5000 | N11: =EDATE(I11,36) -> 47396 | R11: Pending
B19: PORTFOLIO TOTAL | J19: =SUM(J9:J18) -> 1100000 | M19: =SUM(M9:M18) -> 55000

Sheet Investor Portfolio Overview
B2: Czarlie & Ron Investments — Consolidated Investor Portfolio Overview
B3: Select Investor Partner: | C3: Carrei Cyrell R. Mabanag
B4: Investor ID | C4: {=_xlfn.XLOOKUP(C3, 'Investors Details'!$C$9:$C$19, 'Investors Details'!$B$9:$B$19, "")} -> INV-002
B5: TOTAL CAPITAL INVESTED | D5: MONTHLY RETURN LIABILITY | F5: ACTIVE CONTRACTS | H5: LIFETIME PROJECTED PAYOUTS
B6: =SUMIFS('Investors Details'!$J$9:$J$19, 'Investors Details'!$C$9:$C$19, $C$3) -> 500000 | D6: =SUMIFS('Investors Details'!$M$9:$M$19, 'Investors Details'!$C$9:$C$19, $C$3) -> 25000 | F6: =COUNTIFS('Investors Details'!$C$9:$C$19, $C$3, 'Investors Details'!$R$9:$R$19, "Active") -> 1 | H6: =SUMIFS('Investors Details'!$M$9:$M$19, 'Investors Details'!$C$9:$C$19, $C$3)*31 -> 775000
B7: Cumulative Principal Invested | D7: 5.0% Monthly Commitment | F7: Agreements in Force | H7: 31 Active Payout Cycles (155%)
B9: Contract Iterations & Investment Agreements
B10: Investor ID | C10: Contract Number | D10: Investment Iteration | E10: Contract Start Date | F10: Maturity Date | G10: Contract Term | H10: Investment Capital (PHP) | I10: Monthly Rate | J10: Monthly Return (PHP) | K10: Contract Status
B11: =IFERROR(__xludf.DUMMYFUNCTION("IFNA(FILTER({'Investors Details'!$B$9:$B$19, 'Investors Details'!$H$9:$H$19, 'Investors Details'!$G$9:$G$19, 'Investors Details'!$I$9:$I$19, 'Investors Details'!$N$9:$N$19, 'Investors Details'!$L$9:$L$19, 'Investors Details'!$J$9:$J$19, 'Investors Details"&"'!$K$9:$K$19, 'Investors Details'!$M$9:$M$19, 'Investors Details'!$R$9:$R$19}, 'Investors Details'!$C$9:$C$19 = $C$3), ""No active contracts found"")"),"INV-002") -> INV-002 | C11: =IFERROR(__xludf.DUMMYFUNCTION("""COMPUTED_VALUE"""),"CR-2026-003") -> CR-2026-003 | D11: =IFERROR(__xludf.DUMMYFUNCTION("""COMPUTED_VALUE"""),"Initial Investment") -> Initial Investment | E11: =IFERROR(__xludf.DUMMYFUNCTION("""COMPUTED_VALUE"""),46307.0) -> 46307 | F11: =IFERROR(__xludf.DUMMYFUNCTION("""COMPUTED_VALUE"""),47403.0) -> 47403 | G11: =IFERROR(__xludf.DUMMYFUNCTION("""COMPUTED_VALUE"""),"36 Months") -> 36 Months | H11: =IFERROR(__xludf.DUMMYFUNCTION("""COMPUTED_VALUE"""),500000.0) -> 500000 | I11: =IFERROR(__xludf.DUMMYFUNCTION("""COMPUTED_VALUE"""),0.05) -> 0.05 | J11: =IFERROR(__xludf.DUMMYFUNCTION("""COMPUTED_VALUE"""),25000.0) -> 25000 | K11: =IFERROR(__xludf.DUMMYFUNCTION("""COMPUTED_VALUE"""),"Active") -> Active

Sheet Payout Schedule
B2: Czarlie & Ron Investments — 36-Month Master Payout Schedule
B3: Contract Term: 36 Months | Payout Due Date: Approximately 81-Day Initial Operational Cycle (60 Days Shipping, 2 Weeks Sorting and Preparation, 1 Week Customer Collection); Monthly Recurring Thereafter (Adjusted for Weekends and Philippine Holidays) | Return Rate: 5.0% Monthly | M3: Available Contracts
B4: Investor Name: | C4: Carrei Cyrell R. Mabanag | H4: Contract Start: | I4: {=_xlfn.XLOOKUP(C6, 'Investors Details'!$H$9:$H$18, 'Investors Details'!$I$9:$I$18)} -> 46307 | M4: =IFERROR(__xludf.DUMMYFUNCTION("IFERROR(FILTER('Investors Details'!$H$9:$H$19, 'Investors Details'!$C$9:$C$19 = C4), """")"),"CR-2026-003") -> CR-2026-003
B5: Investor ID: | C5: {=_xlfn.XLOOKUP(C4, 'Investors Details'!$C$9:$C$18, 'Investors Details'!$B$9:$B$18, "")} -> INV-002 | H5: Total Projected Monthly Returns: | I5: =SUM(F9:F44) -> 775000
B6: Contract Number: | C6: CR-2026-003 | H6: Total Status Paid: | I6: =SUMIF(G9:G44,"Paid",F9:F44) -> 0
B8: Month # | C8: Disbursement Due Date | D8: Illustrative Monthly Return (5%) | E8: Contract Condition / Rule Applied | F8: Net Payout Amount (PHP) | G8: Disbursement Status | H8: Payment Date / Reference | I8: Notes / Remarks
B9: Month 1 | C9: =IFERROR(__xludf.DUMMYFUNCTION("MAP(SEQUENCE(36), LAMBDA(m, WORKDAY(EDATE($I$4, m) - 1, 1, FILTER('NATIONAL HOLIDAYS'!$B$10:$B$95, 'NATIONAL HOLIDAYS'!$G$10:$G$95=""Closed"")))) "),46338.0) -> 46338 | D9: {=IF(B9:B44<>"", _xlfn.XLOOKUP($C$6, 'Investors Details'!$H$9:$H$19, 'Investors Details'!$M$9:$M$19), "")} -> 25000 | E9: {=IF(B9:B44="", "", IF(ROW(B9:B44)-ROW($B$8)<=2, "Section 4 Deferral (Initial 2 Months)", IF(MONTH(C9:C44)=3, "Section 5 Waiver (March CNY Zero Return)", "Standard Monthly Payout")))} -> Section 4 Deferral (Initial 2 Months) | F9: {=IF(B9:B44="", "", IF(ROW(B9:B44)-ROW($B$8)<=2, 0, IF(MONTH(C9:C44)=3, 0, D9:D44)))} -> 0 | G9: {=IF(B9:B44="", "", IF(ROW(B9:B44)-ROW($B$8)<=2, "Deferred (Mo 1-2)", IF(MONTH(C9:C44)=3, "Waived (CNY March)", "Pending")))} -> Deferred (Mo 1-2) | H9: {=IF(B9:B44="", "", IF(F9:F44=0, "-", ""))} -> - | I9: {=IF(B9:B44="", "", IF(ROW(B9:B44)-ROW($B$8)<=2, "Initial setup grace period", IF(MONTH(C9:C44)=3, "March Return Waived — Section 5", IF(ROW(B9:B44)-ROW($B$8)=36, "Final Scheduled Monthly Return — Return of Original Investment Handled Separately Under Section 8", IF(ROW(B9:B44)-ROW($B$8)=12, "End of Year 1", IF(ROW(B9:B44)-ROW($B$8)=24, "End of Year 2", "Regular monthly payout"))))))} -> Initial setup grace period
B10: Month 2 | C10: =IFERROR(__xludf.DUMMYFUNCTION("""COMPUTED_VALUE"""),46370.0) -> 46370 | D10: 25000 | E10: Section 4 Deferral (Initial 2 Months) | F10: 0 | G10: Deferred (Mo 1-2) | H10: - | I10: Initial setup grace period
B11: Month 3 | C11: =IFERROR(__xludf.DUMMYFUNCTION("""COMPUTED_VALUE"""),46399.0) -> 46399 | D11: 25000 | E11: Standard Monthly Payout | F11: 25000 | G11: Pending | I11: Regular monthly payout
B12: Month 4 | C12: =IFERROR(__xludf.DUMMYFUNCTION("""COMPUTED_VALUE"""),46430.0) -> 46430 | D12: 25000 | E12: Standard Monthly Payout | F12: 25000 | G12: Pending | I12: Regular monthly payout
B13: Month 5 | C13: =IFERROR(__xludf.DUMMYFUNCTION("""COMPUTED_VALUE"""),46458.0) -> 46458 | D13: 25000 | E13: Section 5 Waiver (March CNY Zero Return) | F13: 0 | G13: Waived (CNY March) | H13: - | I13: March Return Waived — Section 5
B14: Month 6 | C14: =IFERROR(__xludf.DUMMYFUNCTION("""COMPUTED_VALUE"""),46489.0) -> 46489 | D14: 25000 | E14: Standard Monthly Payout | F14: 25000 | G14: Pending | I14: Regular monthly payout
B15: Month 7 | C15: =IFERROR(__xludf.DUMMYFUNCTION("""COMPUTED_VALUE"""),46519.0) -> 46519 | D15: 25000 | E15: Standard Monthly Payout | F15: 25000 | G15: Pending | I15: Regular monthly payout
B16: Month 8 | C16: =IFERROR(__xludf.DUMMYFUNCTION("""COMPUTED_VALUE"""),46552.0) -> 46552 | D16: 25000 | E16: Standard Monthly Payout | F16: 25000 | G16: Pending | I16: Regular monthly payout
B17: Month 9 | C17: =IFERROR(__xludf.DUMMYFUNCTION("""COMPUTED_VALUE"""),46580.0) -> 46580 | D17: 25000 | E17: Standard Monthly Payout | F17: 25000 | G17: Pending | I17: Regular monthly payout
B18: Month 10 | C18: =IFERROR(__xludf.DUMMYFUNCTION("""COMPUTED_VALUE"""),46611.0) -> 46611 | D18: 25000 | E18: Standard Monthly Payout | F18: 25000 | G18: Pending | I18: Regular monthly payout
B19: Month 11 | C19: =IFERROR(__xludf.DUMMYFUNCTION("""COMPUTED_VALUE"""),46643.0) -> 46643 | D19: 25000 | E19: Standard Monthly Payout | F19: 25000 | G19: Pending | I19: Regular monthly payout
B20: Month 12 | C20: =IFERROR(__xludf.DUMMYFUNCTION("""COMPUTED_VALUE"""),46672.0) -> 46672 | D20: 25000 | E20: Standard Monthly Payout | F20: 25000 | G20: Pending | I20: End of Year 1
B21: Month 13 | C21: =IFERROR(__xludf.DUMMYFUNCTION("""COMPUTED_VALUE"""),46703.0) -> 46703 | D21: 25000 | E21: Standard Monthly Payout | F21: 25000 | G21: Pending | I21: Regular monthly payout
B22: Month 14 | C22: =IFERROR(__xludf.DUMMYFUNCTION("""COMPUTED_VALUE"""),46734.0) -> 46734 | D22: 25000 | E22: Standard Monthly Payout | F22: 25000 | G22: Pending | I22: Regular monthly payout
B23: Month 15 | C23: =IFERROR(__xludf.DUMMYFUNCTION("""COMPUTED_VALUE"""),46764.0) -> 46764 | D23: 25000 | E23: Standard Monthly Payout | F23: 25000 | G23: Pending | I23: Regular monthly payout
B24: Month 16 | C24: =IFERROR(__xludf.DUMMYFUNCTION("""COMPUTED_VALUE"""),46797.0) -> 46797 | D24: 25000 | E24: Standard Monthly Payout | F24: 25000 | G24: Pending | I24: Regular monthly payout
B25: Month 17 | C25: =IFERROR(__xludf.DUMMYFUNCTION("""COMPUTED_VALUE"""),46825.0) -> 46825 | D25: 25000 | E25: Section 5 Waiver (March CNY Zero Return) | F25: 0 | G25: Waived (CNY March) | H25: - | I25: March Return Waived — Section 5
B26: Month 18 | C26: =IFERROR(__xludf.DUMMYFUNCTION("""COMPUTED_VALUE"""),46855.0) -> 46855 | D26: 25000 | E26: Standard Monthly Payout | F26: 25000 | G26: Pending | I26: Regular monthly payout
B27: Month 19 | C27: =IFERROR(__xludf.DUMMYFUNCTION("""COMPUTED_VALUE"""),46885.0) -> 46885 | D27: 25000 | E27: Standard Monthly Payout | F27: 25000 | G27: Pending | I27: Regular monthly payout
B28: Month 20 | C28: =IFERROR(__xludf.DUMMYFUNCTION("""COMPUTED_VALUE"""),46917.0) -> 46917 | D28: 25000 | E28: Standard Monthly Payout | F28: 25000 | G28: Pending | I28: Regular monthly payout
B29: Month 21 | C29: =IFERROR(__xludf.DUMMYFUNCTION("""COMPUTED_VALUE"""),46946.0) -> 46946 | D29: 25000 | E29: Standard Monthly Payout | F29: 25000 | G29: Pending | I29: Regular monthly payout
B30: Month 22 | C30: =IFERROR(__xludf.DUMMYFUNCTION("""COMPUTED_VALUE"""),46979.0) -> 46979 | D30: 25000 | E30: Standard Monthly Payout | F30: 25000 | G30: Pending | I30: Regular monthly payout
B31: Month 23 | C31: =IFERROR(__xludf.DUMMYFUNCTION("""COMPUTED_VALUE"""),47008.0) -> 47008 | D31: 25000 | E31: Standard Monthly Payout | F31: 25000 | G31: Pending | I31: Regular monthly payout
B32: Month 24 | C32: =IFERROR(__xludf.DUMMYFUNCTION("""COMPUTED_VALUE"""),47038.0) -> 47038 | D32: 25000 | E32: Standard Monthly Payout | F32: 25000 | G32: Pending | I32: End of Year 2
B33: Month 25 | C33: =IFERROR(__xludf.DUMMYFUNCTION("""COMPUTED_VALUE"""),47070.0) -> 47070 | D33: 25000 | E33: Standard Monthly Payout | F33: 25000 | G33: Pending | I33: Regular monthly payout
B34: Month 26 | C34: =IFERROR(__xludf.DUMMYFUNCTION("""COMPUTED_VALUE"""),47099.0) -> 47099 | D34: 25000 | E34: Standard Monthly Payout | F34: 25000 | G34: Pending | I34: Regular monthly payout
B35: Month 27 | C35: =IFERROR(__xludf.DUMMYFUNCTION("""COMPUTED_VALUE"""),47130.0) -> 47130 | D35: 25000 | E35: Standard Monthly Payout | F35: 25000 | G35: Pending | I35: Regular monthly payout
B36: Month 28 | C36: =IFERROR(__xludf.DUMMYFUNCTION("""COMPUTED_VALUE"""),47161.0) -> 47161 | D36: 25000 | E36: Standard Monthly Payout | F36: 25000 | G36: Pending | I36: Regular monthly payout
B37: Month 29 | C37: =IFERROR(__xludf.DUMMYFUNCTION("""COMPUTED_VALUE"""),47189.0) -> 47189 | D37: 25000 | E37: Section 5 Waiver (March CNY Zero Return) | F37: 0 | G37: Waived (CNY March) | H37: - | I37: March Return Waived — Section 5
B38: Month 30 | C38: =IFERROR(__xludf.DUMMYFUNCTION("""COMPUTED_VALUE"""),47220.0) -> 47220 | D38: 25000 | E38: Standard Monthly Payout | F38: 25000 | G38: Pending | I38: Regular monthly payout
B39: Month 31 | C39: =IFERROR(__xludf.DUMMYFUNCTION("""COMPUTED_VALUE"""),47252.0) -> 47252 | D39: 25000 | E39: Standard Monthly Payout | F39: 25000 | G39: Pending | I39: Regular monthly payout
B40: Month 32 | C40: =IFERROR(__xludf.DUMMYFUNCTION("""COMPUTED_VALUE"""),47282.0) -> 47282 | D40: 25000 | E40: Standard Monthly Payout | F40: 25000 | G40: Pending | I40: Regular monthly payout
B41: Month 33 | C41: =IFERROR(__xludf.DUMMYFUNCTION("""COMPUTED_VALUE"""),47311.0) -> 47311 | D41: 25000 | E41: Standard Monthly Payout | F41: 25000 | G41: Pending | I41: Regular monthly payout
B42: Month 34 | C42: =IFERROR(__xludf.DUMMYFUNCTION("""COMPUTED_VALUE"""),47343.0) -> 47343 | D42: 25000 | E42: Standard Monthly Payout | F42: 25000 | G42: Pending | I42: Regular monthly payout
...

Sheet NATIONAL HOLIDAYS
B2: PHILIPPINE NATIONAL HOLIDAYS (2026–2030)
B3: Official 5-Year Master Calendar for Fund Operations, Investment Tenor, and Banking Payout Settlement Schedules
B4: TOTAL HOLIDAYS | D4: REGULAR HOLIDAYS | F4: SPECIAL NON-WORKING DAYS | H4: SPECIAL WORKING DAYS
B5: =COUNTA(B10:B95) -> 86 | D5: =COUNTIF(F10:F95, "Regular Holiday") -> 50 | F5: =COUNTIF(F10:F95, "Special Non-Working Day") -> 31 | H5: =COUNTIF(F10:F95, "Special Working Day") -> 5
B6: 5-Year Master Horizon (2026–2030) | D6: Full Banking & Payout Halt | F6: Trading & Clearing Settlement Halt | H6: Standard Banking Operations
B9: Date | C9: Year | D9: Holiday Name | E9: Day of Week | F9: Holiday Type | G9: Banking Status | H9: Statutory Basis
B10: 46023 | C10: =YEAR(B10) -> 2026 | D10: New Year's Day | E10: =TEXT(B10, "dddd") -> Thursday | F10: Regular Holiday | G10: Closed | H10: R.A. 9492 / Proclamation
B11: 46070 | C11: =YEAR(B11) -> 2026 | D11: Chinese New Year | E11: =TEXT(B11, "dddd") -> Tuesday | F11: Special Non-Working Day | G11: Closed | H11: Presidential Proclamation
B12: 46078 | C12: =YEAR(B12) -> 2026 | D12: EDSA People Power Anniversary | E12: =TEXT(B12, "dddd") -> Wednesday | F12: Special Working Day | G12: Open | H12: Presidential Proclamation
B13: 46114 | C13: =YEAR(B13) -> 2026 | D13: Maundy Thursday | E13: =TEXT(B13, "dddd") -> Thursday | F13: Regular Holiday | G13: Closed | H13: R.A. 9492 / Proclamation
B14: 46115 | C14: =YEAR(B14) -> 2026 | D14: Good Friday | E14: =TEXT(B14, "dddd") -> Friday | F14: Regular Holiday | G14: Closed | H14: R.A. 9492 / Proclamation
B15: 46121 | C15: =YEAR(B15) -> 2026 | D15: Araw ng Kagitingan | E15: =TEXT(B15, "dddd") -> Thursday | F15: Regular Holiday | G15: Closed | H15: R.A. 9492 / Proclamation
B16: 46143 | C16: =YEAR(B16) -> 2026 | D16: Labor Day | E16: =TEXT(B16, "dddd") -> Friday | F16: Regular Holiday | G16: Closed | H16: R.A. 9492 / Proclamation
B17: 46185 | C17: =YEAR(B17) -> 2026 | D17: Independence Day | E17: =TEXT(B17, "dddd") -> Friday | F17: Regular Holiday | G17: Closed | H17: R.A. 9492 / Proclamation
B18: 46255 | C18: =YEAR(B18) -> 2026 | D18: Ninoy Aquino Day | E18: =TEXT(B18, "dddd") -> Friday | F18: Special Non-Working Day | G18: Closed | H18: R.A. 9256 / Proclamation
B19: 46265 | C19: =YEAR(B19) -> 2026 | D19: National Heroes Day | E19: =TEXT(B19, "dddd") -> Monday | F19: Regular Holiday | G19: Closed | H19: R.A. 9492 / Proclamation
B20: 46327 | C20: =YEAR(B20) -> 2026 | D20: All Saints' Day | E20: =TEXT(B20, "dddd") -> Sunday | F20: Special Non-Working Day | G20: Closed | H20: R.A. 9492 / Proclamation
B21: 46328 | C21: =YEAR(B21) -> 2026 | D21: All Souls' Day | E21: =TEXT(B21, "dddd") -> Monday | F21: Special Non-Working Day | G21: Closed | H21: Presidential Proclamation
... B95: 47847 | C95: =YEAR(B95) -> 2030 | D95: Rizal Day | E95: =TEXT(B95, "dddd") -> Monday | F95: Regular Holiday | G95: Closed | H95: R.A. 9492 / Proclamation
